Workbook

Sheet Implementation Tracker
A1: Clause | B1: Sub-Clause | C1: Sub-Clause Title | D1: Task # | E1: Task Description | F1: Responsible | G1: Owner (Name) | H1: Target Date | I1: Status | J1: % Complete | K1: Evidence Required | L1: Regulatory Alignment | M1: Evidence Location | N1: Notes
A2: 4 | B2: 4.1 | C2: Understanding the Organization and Its Context | D2: 1 | E2: Identify internal factors: AI capabilities, legacy systems, data infrastructure, risk culture, governance maturity | F2: CRO, AI Governance Lead, Head of Technology | I2: Not Started | J2: 0% | K2: Organizational context report, PESTLE analysis, AI maturity assessment, AI-to-business mapping | L2: APRA CPS 230
A3: 4 | B3: 4.1 | C3: Understanding the Organization and Its Context | D3: 2 | E3: Identify external factors: financial regulations (APRA CPS 230/234, Basel, MiFID II, DORA, EU AI Act), market conditions | F3: CRO, AI Governance Lead, Head of Technology | I3: Not Started | J3: 0% | K3: Organizational context report, PESTLE analysis, AI maturity assessment, AI-to-business mapping | L3: APRA CPS 230
A4: 4 | B4: 4.1 | C4: Understanding the Organization and Its Context | D4: 3 | E4: Document AI-specific context: AI maturity level, strategic AI roadmap, competitive positioning | F4: CRO, AI Governance Lead, Head of Technology | I4: Not Started | J4: 0% | K4: Organizational context report, PESTLE analysis, AI maturity assessment, AI-to-business mapping | L4: APRA CPS 230
A5: 4 | B5: 4.1 | C5: Understanding the Organization and Its Context | D5: 4 | E5: Conduct PESTLE analysis with financial-services-specific AI considerations | F5: CRO, AI Governance Lead, Head of Technology | I5: Not Started | J5: 0% | K5: Organizational context report, PESTLE analysis, AI maturity assessment, AI-to-business mapping | L5: APRA CPS 230
A6: 4 | B6: 4.1 | C6: Understanding the Organization and Its Context | D6: 5 | E6: Map AI systems to financial services functions: credit scoring, fraud detection, AML/KYC, trading, claims, onboarding, robo-advisory | F6: CRO, AI Governance Lead, Head of Technology | I6: Not Started | J6: 0% | K6: Organizational context report, PESTLE analysis, AI maturity assessment, AI-to-business mapping | L6: APRA CPS 230
A7: 4 | B7: 4.1 | C7: Understanding the Organization and Its Context | D7: 6 | E7: Assess interaction between AI governance and existing financial risk frameworks (operational risk, model risk, conduct risk) | F7: CRO, AI Governance Lead, Head of Technology | I7: Not Started | J7: 0% | K7: Organizational context report, PESTLE analysis, AI maturity assessment, AI-to-business mapping | L7: APRA CPS 230
A8: 4 | B8: 4.2 | C8: Needs and Expectations of Interested Parties | D8: 1 | E8: Identify interested parties: customers, regulators (APRA, ASIC, FCA, ECB, SEC), shareholders, auditors, data subjects | F8: AI Governance Lead, Legal/Compliance, Regulatory Affairs | I8: Not Started | J8: 0% | K8: Interested parties register, regulatory requirements matrix, stakeholder mapping, horizon scanning log | L8: Multiple (APRA, Basel, EU AI Act)
A9: 4 | B9: 4.2 | C9: Needs and Expectations of Interested Parties | D9: 2 | E9: Document regulatory expectations: SR 11-7, APRA CPG 235, CPS 234, EU AI Act risk tiers | F9: AI Governance Lead, Legal/Compliance, Regulatory Affairs | I9: Not Started | J9: 0% | K9: Interested parties register, regulatory requirements matrix, stakeholder mapping, horizon scanning log | L9: Multiple (APRA, Basel, EU AI Act)
A10: 4 | B10: 4.2 | C10: Needs and Expectations of Interested Parties | D10: 3 | E10: Map stakeholder concerns to AI systems (e.g., customer fairness in credit decisions, explainability) | F10: AI Governance Lead, Legal/Compliance, Regulatory Affairs | I10: Not Started | J10: 0% | K10: Interested parties register, regulatory requirements matrix, stakeholder mapping, horizon scanning log | L10: Multiple (APRA, Basel, EU AI Act)
A11: 4 | B11: 4.2 | C11: Needs and Expectations of Interested Parties | D11: 4 | E11: Document requirements from financial industry bodies (OECD AI Principles, FSB recommendations) | F11: AI Governance Lead, Legal/Compliance, Regulatory Affairs | I11: Not Started | J11: 0% | K11: Interested parties register, regulatory requirements matrix, stakeholder mapping, horizon scanning log | L11: Multiple (APRA, Basel, EU AI Act)
A12: 4 | B12: 4.2 | C12: Needs and Expectations of Interested Parties | D12: 5 | E12: Assess third-party expectations from banking partners, payment networks, outsourcing providers | F12: AI Governance Lead, Legal/Compliance, Regulatory Affairs | I12: Not Started | J12: 0% | K12: Interested parties register, regulatory requirements matrix, stakeholder mapping, horizon scanning log | L12: Multiple (APRA, Basel, EU AI Act)
A13: 4 | B13: 4.2 | C13: Needs and Expectations of Interested Parties | D13: 6 | E13: Establish ongoing regulatory horizon scanning and stakeholder engagement process | F13: AI Governance Lead, Legal/Compliance, Regulatory Affairs | I13: Not Started | J13: 0% | K13: Interested parties register, regulatory requirements matrix, stakeholder mapping, horizon scanning log | L13: Multiple (APRA, Basel, EU AI Act)
... A54: 6 | B54: 6.1.4 | C54: AI System Impact Assessment | D54: 6 | E54: Document results with links to control requirements and remediation actions | F54: AI Governance Lead, Model Risk, Ethics Committee, Compliance | I54: Not Started | J54: 0% | K54: Impact assessment template (FS-specific), completed assessments, disparate impact analyses, PIAs | L54: EU AI Act, Fair Lending, APPs
A55: 6 | B55: 6.2 | C55: AI Objectives and Planning | D55: 1 | E55: Establish measurable objectives: accuracy, fairness metrics, explainability coverage, time-to-validation | F55: CRO, AI Governance Lead, Business Line Heads | I55: Not Started | J55: 0% | K55: AI Objectives, KRI/KPI dashboard, Board reporting pack, review records
A56: 6 | B56: 6.2 | C56: AI Objectives and Planning | D56: 2 | E56: Define compliance objectives: 100% high-risk AI validated pre-deployment, regulator SLAs met | F56: CRO, AI Governance Lead, Business Line Heads | I56: Not Started | J56: 0% | K56: AI Objectives, KRI/KPI dashboard, Board reporting pack, review records
A57: 6 | B57: 6.2 | C57: AI Objectives and Planning | D57: 3 | E57: Set customer outcome objectives: reduced unfair denials, improved transparency | F57: CRO, AI Governance Lead, Business Line Heads | I57: Not Started | J57: 0% | K57: AI Objectives, KRI/KPI dashboard, Board reporting pack, review records
A58: 6 | B58: 6.2 | C58: AI Objectives and Planning | D58: 4 | E58: Define actions, resources, responsible person, timeline, KPIs for each objective | F58: CRO, AI Governance Lead, Business Line Heads | I58: Not Started | J58: 0% | K58: AI Objectives, KRI/KPI dashboard, Board reporting pack, review records
A59: 6 | B59: 6.2 | C59: AI Objectives and Planning | D59: 5 | E59: Align AI objectives with institutional KRIs; report to Board Risk Committee | F59: CRO, AI Governance Lead, Business Line Heads | I59: Not Started | J59: 0% | K59: AI Objectives, KRI/KPI dashboard, Board reporting pack, review records
A60: 6 | B60: 6.3 | C60: Planning of Changes | D60: 1 | E60: Establish change management aligned with IT change and model change procedures | F60: AI Governance Lead, Change Management, Model Risk | I60: Not Started | J60: 0% | K60: Change procedure, materiality matrix, change log, PIR records
A61: 6 | B61: 6.3 | C61: Planning of Changes | D61: 2 | E61: Define materiality thresholds for changes requiring re-validation or re-approval | F61: AI Governance Lead, Change Management, Model Risk | I61: Not Started | J61: 0% | K61: Change procedure, materiality matrix, change log, PIR records
A62: 6 | B62: 6.3 | C62: Planning of Changes | D62: 3 | E62: Assess regulatory impact of AIMS changes (e.g., new AI use case requiring notification) | F62: AI Governance Lead, Change Management, Model Risk | I62: Not Started | J62: 0% | K62: Change procedure, materiality matrix, change log, PIR records
A63: 6 | B63: 6.3 | C63: Planning of Changes | D63: 4 | E63: Document change requests, risk assessments, approvals, post-implementation reviews | F63: AI Governance Lead, Change Management, Model Risk | I63: Not Started | J63: 0% | K63: Change procedure, materiality matrix, change log, PIR records
A64: 7 | B64: 7.1 | C64: Resources | D64: 1 | E64: Determine resources: AI governance team, model validation, data scientists, compliance, AI audit capability | F64: CFO, CRO, HR, CTO | I64: Not Started | J64: 0% | K64: Resource plan, budget allocation, capability gap analysis, headcount plans
A65: 7 | B65: 7.1 | C65: Resources | D65: 2 | E65: Assess capability gaps in MRM, AI ethics, explainability, fairness testing | F65: CFO, CRO, HR, CTO | I65: Not Started | J65: 0% | K65: Resource plan, budget allocation, capability gap analysis, headcount plans
A66: 7 | B66: 7.1 | C66: Resources | D66: 3 | E66: Budget for: governance tools, independent validation, external expertise, regulatory engagement | F66: CFO, CRO, HR, CTO | I66: Not Started | J66: 0% | K66: Resource plan, budget allocation, capability gap analysis, headcount plans
A67: 7 | B67: 7.1 | C67: Resources | D67: 4 | E67: Ensure adequate 2L validation resources independent of 1L development | F67: CFO, CRO, HR, CTO | I67: Not Started | J67: 0% | K67: Resource plan, budget allocation, capability gap analysis, headcount plans
A68: 7 | B68: 7.2 | C68: Competence | D68: 1 | E68: Define competencies: model developers (ML + domain), validators (stats + regulation), AI auditors | F68: HR, AI Governance Lead, Training, Model Risk | I68: Not Started | J68: 0% | K68: Competency framework (FS-specific), training plan, Board AI literacy program, records | L68: APRA CPS 520
A69: 7 | B69: 7.2 | C69: Competence | D69: 2 | E69: Require understanding of relevant regulations for all AI staff | F69: HR, AI Governance Lead, Training, Model Risk | I69: Not Started | J69: 0% | K69: Competency framework (FS-specific), training plan, Board AI literacy program, records | L69: APRA CPS 520
A70: 7 | B70: 7.2 | C70: Competence | D70: 3 | E70: Establish ongoing training: responsible AI, bias testing, explainability, financial regulation | F70: HR, AI Governance Lead, Training, Model Risk | I70: Not Started | J70: 0% | K70: Competency framework (FS-specific), training plan, Board AI literacy program, records | L70: APRA CPS 520
A71: 7 | B71: 7.2 | C71: Competence | D71: 4 | E71: Ensure Board and senior management receive AI literacy training for effective oversight | F71: HR, AI Governance Lead, Training, Model Risk | I71: Not Started | J71: 0% | K71: Competency framework (FS-specific), training plan, Board AI literacy program, records | L71: APRA CPS 520
A72: 7 | B72: 7.2 | C72: Competence | D72: 5 | E72: Retain evidence: qualifications, certifications (FRM, PRM, AI-specific), training records | F72: HR, AI Governance Lead, Training, Model Risk | I72: Not Started | J72: 0% | K72: Competency framework (FS-specific), training plan, Board AI literacy program, records | L72: APRA CPS 520
A73: 7 | B73: 7.3 | C73: Awareness | D73: 1 | E73: Ensure all staff aware of AI policy and responsibilities | F73: AI Governance Lead, HR, Communications, Compliance | I73: Not Started | J73: 0% | K73: Awareness materials, attendance records, scenario exercise records, staff surveys
A74: 7 | B74: 7.3 | C74: Awareness | D74: 2 | E74: Targeted awareness: front-office (explaining AI to customers), operations (monitoring), compliance (regulatory) | F74: AI Governance Lead, HR, Communications, Compliance | I74: Not Started | J74: 0% | K74: Awareness materials, attendance records, scenario exercise records, staff surveys
A75: 7 | B75: 7.3 | C75: Awareness | D75: 3 | E75: Raise awareness of generative AI risks: data leakage, hallucination, IP, client confidentiality | F75: AI Governance Lead, HR, Communications, Compliance | I75: Not Started | J75: 0% | K75: Awareness materials, attendance records, scenario exercise records, staff surveys
A76: 7 | B76: 7.3 | C76: Awareness | D76: 4 | E76: Scenario-based training: biased lending decision, fraud model excessive false positives | F76: AI Governance Lead, HR, Communications, Compliance | I76: Not Started | J76: 0% | K76: Awareness materials, attendance records, scenario exercise records, staff surveys
A77: 7 | B77: 7.3 | C77: Awareness | D77: 5 | E77: Ensure understanding of whistleblowing and escalation channels for AI concerns | F77: AI Governance Lead, HR, Communications, Compliance | I77: Not Started | J77: 0% | K77: Awareness materials, attendance records, scenario exercise records, staff surveys
A78: 7 | B78: 7.4 | C78: Communication | D78: 1 | E78: Define communication plan: internal (Board, committees, business lines) and external (regulators, customers) | F78: AI Governance Lead, Regulatory Affairs, Customer Experience | I78: Not Started | J78: 0% | K78: Communication plan, regulatory engagement log, customer disclosure templates, incident protocol | L78: Consumer protection
A79: 7 | B79: 7.4 | C79: Communication | D79: 2 | E79: Establish regulatory communication protocols: proactive engagement, inquiry response, breach notification | F79: AI Governance Lead, Regulatory Affairs, Customer Experience | I79: Not Started | J79: 0% | K79: Communication plan, regulatory engagement log, customer disclosure templates, incident protocol | L79: Consumer protection
A80: 7 | B80: 7.4 | C80: Communication | D80: 3 | E80: Define customer communication standards: right to explanation, complaints handling for AI outcomes | F80: AI Governance Lead, Regulatory Affairs, Customer Experience | I80: Not Started | J80: 0% | K80: Communication plan, regulatory engagement log, customer disclosure templates, incident protocol | L80: Consumer protection
...

Sheet Dashboard
A1: ISO 42001 Implementation Dashboard — Financial Services
A3: Overall Progress Summary
A4: Metric | B4: Value
A5: Total Tasks | B5: =COUNTA('Implementation Tracker'!E2:E133) -> 132
A6: Not Started | B6: =COUNTIF('Implementation Tracker'!I2:I133,"Not Started") -> 132
A7: In Progress | B7: =COUNTIF('Implementation Tracker'!I2:I133,"In Progress") -> 0
A8: Under Review | B8: =COUNTIF('Implementation Tracker'!I2:I133,"Under Review") -> 0
A9: Complete | B9: =COUNTIF('Implementation Tracker'!I2:I133,"Complete") -> 0
A10: N/A | B10: =COUNTIF('Implementation Tracker'!I2:I133,"N/A") -> 0
A11: Completion Rate (%) | B11: =IF(B5>0,B8/B5*100,0) -> 0
A13: Progress by Clause
A14: Clause | B14: Title | C14: Total Tasks | D14: Complete | E14: % Complete
A15: 4 | B15: Context of the Organization | C15: =COUNTIF('Implementation Tracker'!A2:A133,"4") -> 22 | D15: =COUNTIFS('Implementation Tracker'!A2:A133,"4",'Implementation Tracker'!I2:I133,"Complete") -> 0 | E15: =IF(C15>0,D15/C15*100,0) -> 0
A16: 5 | B16: Leadership | C16: =COUNTIF('Implementation Tracker'!A2:A133,"5") -> 18 | D16: =COUNTIFS('Implementation Tracker'!A2:A133,"5",'Implementation Tracker'!I2:I133,"Complete") -> 0 | E16: =IF(C16>0,D16/C16*100,0) -> 0
A17: 6 | B17: Planning | C17: =COUNTIF('Implementation Tracker'!A2:A133,"6") -> 22 | D17: =COUNTIFS('Implementation Tracker'!A2:A133,"6",'Implementation Tracker'!I2:I133,"Complete") -> 0 | E17: =IF(C17>0,D17/C17*100,0) -> 0
A18: 7 | B18: Support | C18: =COUNTIF('Implementation Tracker'!A2:A133,"7") -> 23 | D18: =COUNTIFS('Implementation Tracker'!A2:A133,"7",'Implementation Tracker'!I2:I133,"Complete") -> 0 | E18: =IF(C18>0,D18/C18*100,0) -> 0
A19: 8 | B19: Operation | C19: =COUNTIF('Implementation Tracker'!A2:A133,"8") -> 21 | D19: =COUNTIFS('Implementation Tracker'!A2:A133,"8",'Implementation Tracker'!I2:I133,"Complete") -> 0 | E19: =IF(C19>0,D19/C19*100,0) -> 0
A20: 9 | B20: Performance Evaluation | C20: =COUNTIF('Implementation Tracker'!A2:A133,"9") -> 16 | D20: =COUNTIFS('Implementation Tracker'!A2:A133,"9",'Implementation Tracker'!I2:I133,"Complete") -> 0 | E20: =IF(C20>0,D20/C20*100,0) -> 0
A21: 10 | B21: Improvement | C21: =COUNTIF('Implementation Tracker'!A2:A133,"10") -> 10 | D21: =COUNTIFS('Implementation Tracker'!A2:A133,"10",'Implementation Tracker'!I2:I133,"Complete") -> 0 | E21: =IF(C21>0,D21/C21*100,0) -> 0

Sheet Regulatory Alignment
A1: Regulation / Standard | B1: Jurisdiction | C1: Key AI Requirements | D1: Relevant ISO 42001 Clauses | E1: Compliance Status
A2: APRA CPS 230 (Operational Risk) | B2: Australia | C2: Operational resilience incl. AI; third-party risk; critical operations | D2: 4.3, 8.1 | E2: Not Assessed
A3: APRA CPS 234 (Information Security) | B3: Australia | C3: Information security for AI systems; data protection; testing | D3: 4.2, 7.5, 8.1 | E3: Not Assessed
A4: APRA CPG 235 (Data Risk) | B4: Australia | C4: Data governance, quality, lineage for AI/analytics | D4: 7.5, 8.1, 8.2 | E4: Not Assessed
A5: APRA CPS 220 (Risk Management) | B5: Australia | C5: Operational risk framework incl. AI; risk appetite; Board oversight | D5: 5.1, 6.1, 9.3 | E5: Not Assessed
A6: EU AI Act | B6: EU | C6: Risk-based AI classification; high-risk requirements for credit/insurance | D6: 4.3, 6.1.4, 8.3 | E6: Not Assessed
A7: DORA | B7: EU | C7: ICT risk management incl. AI; third-party concentration; incident reporting | D7: 8.1, 10.2 | E7: Not Assessed
A8: SR 11-7 (Model Risk Management) | B8: USA (Fed/OCC) | C8: Model validation, governance, monitoring; independent validation | D8: 5.2, 5.3, 8.1, 9.2 | E8: Not Assessed
A9: FCA / PRA AI Guidance | B9: UK | C9: Consumer duty; fairness; explainability; accountability | D9: 5.2, 6.1.4, 8.4 | E9: Not Assessed
A10: MiFID II / MiFIR | B10: EU | C10: Algorithmic trading controls; market conduct; best execution | D10: 8.1, 8.3 | E10: Not Assessed
A11: Basel III/IV (BCBS 239) | B11: Global | C11: OpRisk capital; model risk; data aggregation | D11: 6.1, 8.2, 9.1 | E11: Not Assessed
A12: OECD AI Principles | B12: Global | C12: Transparency, accountability, robustness, fairness | D12: 5.2, 6.1 | E12: Not Assessed
... A14: GDPR (where applicable) | B14: EU | C14: Right to explanation (Art. 22); DPIAs; data minimisation | D14: 6.1.4, 7.4, 7.5 | E14: Not Assessed

Sheet Document Register
A1: # | B1: Document Name | C1: Clause Ref | D1: Regulatory Alignment | E1: Owner | F1: Version | G1: Date Created | H1: Last Reviewed | I1: Status | J1: Location/Link
A2: 1 | B2: AIMS Scope Statement | C2: 4.3 | D2: APRA CPS 230 | I2: Draft
A3: 2 | B3: Organizational Context Report | C3: 4.1 | I3: Draft
A4: 3 | B4: Interested Parties & Regulatory Register | C4: 4.2 | D4: Multiple | I4: Draft
A5: 4 | B5: AIMS Process Map (Three Lines of Defence) | C5: 4.4 | D5: SR 11-7, APRA | I5: Draft
A6: 5 | B6: AI Policy (Board-approved) | C6: 5.2 | D6: SR 11-7, APRA, FCA | I6: Draft
A7: 6 | B7: Generative AI Acceptable Use Policy | C7: 5.2 | I7: Draft
A8: 7 | B8: RACI Matrix / Governance Org Chart | C8: 5.3 | D8: SR 11-7 | I8: Draft
A9: 8 | B9: AI Risk Assessment Methodology | C9: 6.1 | D9: CPS 220, Basel | I9: Draft
A10: 9 | B10: AI Risk Register (integrated) | C10: 6.1/8.2 | D10: CPS 220 | I10: Draft
A11: 10 | B11: AI Impact Assessment Methodology | C11: 6.1.4 | D11: EU AI Act, APPs | I11: Draft
A12: 11 | B12: Disparate Impact Analysis Reports | C12: 6.1.4 | D12: Fair lending | I12: Draft
A13: 12 | B13: AI Objectives & KRIs/KPIs | C13: 6.2 | I13: Draft
A14: 13 | B14: Statement of Applicability (SoA) | C14: 8.3 | I14: Draft
A15: 14 | B15: Risk Treatment Plan | C15: 8.3 | I15: Draft
A16: 15 | B16: Model Lifecycle Procedure | C16: 8.1 | D16: SR 11-7 | I16: Draft
A17: 16 | B17: Model Documentation Standards | C17: 7.5 | D17: SR 11-7, APRA | I17: Draft
A18: 17 | B18: Model Inventory | C18: 7.5/8.1 | D18: SR 11-7 | I18: Draft
A19: 18 | B19: Third-Party AI Due Diligence Records | C19: 8.1 | D19: CPS 230, DORA | I19: Draft
A20: 19 | B20: Competency Framework (FS-specific) | C20: 7.2 | I20: Draft
A21: 20 | B21: Training Records (incl. Board AI literacy) | C21: 7.2 | D21: APRA CPS 520 | I21: Draft
A22: 21 | B22: Communication Plan | C22: 7.4 | I22: Draft
A23: 22 | B23: Customer Disclosure Templates | C23: 7.4/8.4 | D23: Consumer protection | I23: Draft
A24: 23 | B24: Monitoring Plan & KPI Dashboard | C24: 9.1 | I24: Draft
A25: 24 | B25: Model Validation Reports | C25: 8.1/9.1 | D25: SR 11-7 | I25: Draft
A26: 25 | B26: Internal AI Audit Reports | C26: 9.2 | I26: Draft
A27: 26 | B27: Management Review / Board Papers | C27: 9.3 | D27: CPS 220 | I27: Draft
A28: 27 | B28: NC & Corrective Action Log | C28: 10.2 | D28: Breach reporting | I28: Draft
A29: 28 | B29: Continual Improvement Register | C29: 10.1 | I29: Draft

Sheet Timeline
A1: Month | B1: Phase | C1: Focus Area | D1: Key Milestones | E1: Status
A2: 1 | B2: Phase 1: Initiation | C2: Board Endorsement & Setup | D2: Board resolution, project team, budget, regulatory advisor engaged | E2: Not Started
A3: 2 | B3: Phase 1: Initiation | C3: Regulatory Mapping | D3: Regulatory requirements mapped to ISO 42001, gap analysis initiated | E3: Not Started
A4: 3 | B4: Phase 1: Initiation | C4: Gap Analysis & Scope | D4: Gap analysis complete, scope defined, AI/model inventory, risk classification | E4: Not Started
A5: 4 | B5: Phase 2: Design | C5: AI Policy & Risk Framework | D5: AI Policy board-approved, risk methodology aligned to MRM, risk appetite set | E5: Not Started
A6: 5 | B6: Phase 2: Design | C6: Risk & Impact Assessments | D6: Risk assessments complete, disparate impact analyses, impact assessments | E6: Not Started
A7: 6 | B7: Phase 2: Design | C7: Controls & SoA | D7: Controls selected per risk tier, SoA drafted, validation procedures designed | E7: Not Started
A8: 7 | B8: Phase 2: Design | C8: Procedures & Documentation | D8: Procedures finalized, model documentation standards, training materials ready | E8: Not Started
A9: 8-9 | B9: Phase 3: Implementation | C9: Rollout | D9: Processes operational, Three Lines trained, model inventory populated | E9: Not Started
A10: 10-11 | B10: Phase 3: Implementation | C10: Monitoring & Evidence | D10: Dashboards live, validation pipeline, 3+ months evidence | E10: Not Started
A11: 12 | B11: Phase 3: Implementation | C11: Operational Maturity | D11: Full evidence, customer outcome testing, model benchmarks | E11: Not Started
A12: 13 | B12: Phase 4: Assurance | C12: Internal Audit | D12: Full AI audit, findings documented, corrective actions initiated | E12: Not Started
... A15: 16-18 | B15: Phase 4: Assurance | C15: Certification Audit | D15: Stage 1 (documentation) and Stage 2 (on-site), surveillance planning | E15: Not Started

Sheet AI Use Cases
A1: AI Use Case | B1: Business Line | C1: Risk Tier | D1: Key Concerns | E1: In Scope? | F1: System Owner | G1: Validation Status | H1: Last Validated
A2: Credit scoring / lending decisions | B2: Retail/Corporate Banking | C2: High | D2: Bias, fair lending, explainability, disparate impact | E2: Yes
A3: Fraud detection | B3: Operations/Risk | C3: High | D3: False positives, model drift, adversarial attacks, real-time performance | E3: Yes
A4: AML / KYC / sanctions screening | B4: Compliance | C4: High | D4: False negatives, alert fatigue, regulatory expectations, data quality | E4: Yes
A5: Algorithmic / HF trading | B5: Markets/Trading | C5: High | D5: Market integrity, circuit breakers, flash crash, conduct risk, MiFID II | E5: Yes
A6: Insurance pricing / underwriting | B6: Insurance | C6: High | D6: Discrimination, proxy variables, transparency, customer outcomes | E6: Yes
A7: Robo-advisory / wealth management | B7: Wealth | C7: High | D7: Suitability, best interest duty, personalisation risks | E7: Yes
A8: Customer service chatbots / LLMs | B8: Customer Experience | C8: Medium | D8: Hallucination, data leakage, complaints, misinformation, conduct | E8: Yes
A9: Customer onboarding / identity verification | B9: Operations | C9: Medium | D9: Biometric bias, privacy, false rejection, accessibility | E9: Yes
A10: Collections / debt management | B10: Operations | C10: Medium | D10: Vulnerable customer identification, conduct risk, fair treatment | E10: Yes
A11: Internal analytics / BI / reporting | B11: Various | C11: Low | D11: Data quality, decision reliance, governance proportionality | E11: Yes
A12: Process automation (RPA + AI) | B12: Operations | C12: Low | D12: Error propagation, monitoring, change management | E12: Yes
